Workbook

Sheet README
A1: Gr(4,11) test: 9 grid columns as rows x 11 D-groups as columns
A2: Rows = grid columns 1..9 of the 9x29 grid (cells 37-297). Columns = D1..D11 (D1 lines 1-11, D2 12-14, D3 15, D4 16, D5 17-18, D6 19, D7 20-21, D8 22-26, D9 27, D10 28, D11 29).
A3: Entry (row c, column D) = sum of all values in grid column c inside D-group D. Zones: grey (each of 114 names counted at the cell numbered by its value), white (99 static names), S3 (216 at line 20 col 9), blue (99 dynamic values).
A4: Sheets: Zones_* (blue font = values computed from your lists in Python), Total (formulas = sum of the four zone sheets), Combos_126 (one row per choice of 4 rows; counts by formula from Minors), Minors (all 126 x 330 exact 4x4 minors, Python-computed integers, colour = sign), Quad_summary, Column_roles, Number_hunt.
A5: Gr>=0 test: a 4-plane is in Gr>=0(4,11) if all 330 minors have the same sign (zeros allowed). Flipping the sign of one row flips all minors, so 'all negative' counts too. Column order used: D1..D11.
A6: Source of values: your pasted lists (L47, N31, Y21, 15 rising pairs) and grid. Grey-cell rule (name sits in the cell numbered by its value) is my reading, confirmed by the column sums 1327,1512,414,1213,1132,1425,874,881,1017 = 9795.

Sheet Tests_reference
A1: ID | B1: Test | C1: Setup | D1: Result (exact) | E1: Status
A2: T0 | B2: Grid reconstruction check | C2: Grey = cell numbered by name value; whites placed from cell 296 backward; blue = even D-groups from cell 136 | D2: 62 distinct grey cells, all in odd D; 99 free odd cells = 99 whites; all pasted white labels and all 11 blue rows match; grey column sums 1327,1512,414,1213,1132,1425,874,881,1017 = 9795 | E2: verified
A3: T1 | B3: Per-name test | C3: Grey, white, D7 (216), blue cells in four different D-groups | D3: 40 pass, 59 fail: 44 grey=white D, 14 white in D7, 1 (L14) both. D7: 15 white + 216 + 2 grey (211, 217). Same result if the dynamic grey cell is used for rising names | E3: verified; criterion is descriptive, not derived
A4: T2 | B4: 4 x 9 columns (rows S1..S4, grid columns as columns) | C4: 126 minors; S3 has only column 9 | D4: 70 zero (forced, columns without 9), 56 nonzero (26 +, 30 -); 56 = 216 x 3x3 minors of grey/white/blue | E4: verified
A5: T3 | B5: Flat 4 x 11 (rows S1..S4, columns D1..D11) | C5: Zero pattern only | D5: 50 nonzero of 330 (28 +, 22 -); 9,120 of 11! column orders give one sign; random matrices with same zero pattern give same counts | E5: from earlier chat; 4x11 recomputed here
A6: T4 | B6: 9 x 11 full (rows = grid columns, columns = D) | C6: 126 choices of 4 rows, 330 minors each, natural order | D6: 125 choices with all 330 nonzero, 1 with 329 (rows 2-3-6-7, D2-D4-D6-D8 = 0); totals 20,720 +, 20,859 -, 1 zero; no choice in Gr>=0; local search over column orders: best 49 minority-sign minors | E6: verified (search heuristic)
A7: T5 | B7: 62 layout (grey only, 114 names) | C7: Same 126 choices | D7: 42 rank 4, 84 rank<4; 39 in Gr>=0 (21 +, 18 -), 3 mixed (1-2-4-9, 1-4-6-9, 1-4-8-9); grey entries only in D1, D3, D5, D7, D9, D11 | E7: verified; boundary points (1, 2, 4 nonzero minors)
A8: T6 | B8: 62 + 216 (216 at row 9, D7) | C8: Same 126 choices | D8: 27 in Gr>=0 (13 +, 14 -), 15 mixed, 84 rank<4; 12 choices (containing 1 and 9) each gain one opposite-sign minor; 27 survivors = 12 without row 9 + 15 with row 9 untouched | E8: verified
A9: T7 | B9: Adding the last zone | C9: 62+216+blue, 62+216+white, full | D9: All 126 choices mixed, rank 4, in each case: 0 survivors. White adds only odd-D minors (max 15 per choice), blue up to 294 | E9: verified
A10: T8 | B10: Grey variants | C10: static 99 only / dynamic 99 only / both 114 | D10: static: 15 rank-4 choices, all Gr>=0, 216 changes nothing; dynamic: 31 Gr>=0, 22 with 216; both: 39, 27 with 216 | E10: verified
A11: T9 | B11: Row 5 | C11: Features | D11: 62 layout: rows 3,5,7 hold D1 only; rows 2,6,8 hold D1 and D5 only; full layout: no special feature (avg minority 154.5 vs 154-157); centre cell 167 (line 15, D3, col 5) holds Y8 = 79; dynamic median = 79 | E11: verified
A12: Open | B12: Frequency test, first-11-lines candidate, 2D curl attachment for B and C, static 99 against its own 11 D | E12: not done

Sheet Combos_126
A1: # | B1: Rows chosen | C1: Positive minors | D1: Negative minors | E1: Zero minors | F1: Nonzero | G1: Minority sign count | H1: In Gr>=0? (all same sign) | I1: Min |minor| nonzero | J1: Max |minor|
A2: 1 | B2: 1-2-3-4 | C2: =COUNTIF(Minors!B2:LS2,">0") -> 182 | D2: =COUNTIF(Minors!B2:LS2,"<0") -> 148 | E2: =COUNTIF(Minors!B2:LS2,0) -> 0 | F2: =C2+D2 -> 330 | G2: =MIN(C2,D2) -> 148 | H2: =IF(F2=0,"rank<4",IF(G2=0,"YES","no")) -> no | I2: =MIN(MIN(Minors!B2:LS2),-MAX(Minors!B2:LS2))*0+SMALL(Minors!B2:LS2,COUNTIF(Minors!B2:LS2,"<0")+E2+1) -> 45 | J2: =MAX(MAX(Minors!B2:LS2),-MIN(Minors!B2:LS2)) -> 3164226470
A3: 2 | B3: 1-2-3-5 | C3: =COUNTIF(Minors!B3:LS3,">0") -> 186 | D3: =COUNTIF(Minors!B3:LS3,"<0") -> 144 | E3: =COUNTIF(Minors!B3:LS3,0) -> 0 | F3: =C3+D3 -> 330 | G3: =MIN(C3,D3) -> 144 | H3: =IF(F3=0,"rank<4",IF(G3=0,"YES","no")) -> no | I3: =MIN(MIN(Minors!B3:LS3),-MAX(Minors!B3:LS3))*0+SMALL(Minors!B3:LS3,COUNTIF(Minors!B3:LS3,"<0")+E3+1) -> 1476 | J3: =MAX(MAX(Minors!B3:LS3),-MIN(Minors!B3:LS3)) -> 6871701069
A4: 3 | B4: 1-2-3-6 | C4: =COUNTIF(Minors!B4:LS4,">0") -> 183 | D4: =COUNTIF(Minors!B4:LS4,"<0") -> 147 | E4: =COUNTIF(Minors!B4:LS4,0) -> 0 | F4: =C4+D4 -> 330 | G4: =MIN(C4,D4) -> 147 | H4: =IF(F4=0,"rank<4",IF(G4=0,"YES","no")) -> no | I4: =MIN(MIN(Minors!B4:LS4),-MAX(Minors!B4:LS4))*0+SMALL(Minors!B4:LS4,COUNTIF(Minors!B4:LS4,"<0")+E4+1) -> 704 | J4: =MAX(MAX(Minors!B4:LS4),-MIN(Minors!B4:LS4)) -> 4254988118
A5: 4 | B5: 1-2-3-7 | C5: =COUNTIF(Minors!B5:LS5,">0") -> 178 | D5: =COUNTIF(Minors!B5:LS5,"<0") -> 152 | E5: =COUNTIF(Minors!B5:LS5,0) -> 0 | F5: =C5+D5 -> 330 | G5: =MIN(C5,D5) -> 152 | H5: =IF(F5=0,"rank<4",IF(G5=0,"YES","no")) -> no | I5: =MIN(MIN(Minors!B5:LS5),-MAX(Minors!B5:LS5))*0+SMALL(Minors!B5:LS5,COUNTIF(Minors!B5:LS5,"<0")+E5+1) -> 2637 | J5: =MAX(MAX(Minors!B5:LS5),-MIN(Minors!B5:LS5)) -> 3949988358
A6: 5 | B6: 1-2-3-8 | C6: =COUNTIF(Minors!B6:LS6,">0") -> 180 | D6: =COUNTIF(Minors!B6:LS6,"<0") -> 150 | E6: =COUNTIF(Minors!B6:LS6,0) -> 0 | F6: =C6+D6 -> 330 | G6: =MIN(C6,D6) -> 150 | H6: =IF(F6=0,"rank<4",IF(G6=0,"YES","no")) -> no | I6: =MIN(MIN(Minors!B6:LS6),-MAX(Minors!B6:LS6))*0+SMALL(Minors!B6:LS6,COUNTIF(Minors!B6:LS6,"<0")+E6+1) -> 3215 | J6: =MAX(MAX(Minors!B6:LS6),-MIN(Minors!B6:LS6)) -> 11235516366
A7: 6 | B7: 1-2-3-9 | C7: =COUNTIF(Minors!B7:LS7,">0") -> 175 | D7: =COUNTIF(Minors!B7:LS7,"<0") -> 155 | E7: =COUNTIF(Minors!B7:LS7,0) -> 0 | F7: =C7+D7 -> 330 | G7: =MIN(C7,D7) -> 155 | H7: =IF(F7=0,"rank<4",IF(G7=0,"YES","no")) -> no | I7: =MIN(MIN(Minors!B7:LS7),-MAX(Minors!B7:LS7))*0+SMALL(Minors!B7:LS7,COUNTIF(Minors!B7:LS7,"<0")+E7+1) -> 788 | J7: =MAX(MAX(Minors!B7:LS7),-MIN(Minors!B7:LS7)) -> 13719019960
A8: 7 | B8: 1-2-4-5 | C8: =COUNTIF(Minors!B8:LS8,">0") -> 148 | D8: =COUNTIF(Minors!B8:LS8,"<0") -> 182 | E8: =COUNTIF(Minors!B8:LS8,0) -> 0 | F8: =C8+D8 -> 330 | G8: =MIN(C8,D8) -> 148 | H8: =IF(F8=0,"rank<4",IF(G8=0,"YES","no")) -> no | I8: =MIN(MIN(Minors!B8:LS8),-MAX(Minors!B8:LS8))*0+SMALL(Minors!B8:LS8,COUNTIF(Minors!B8:LS8,"<0")+E8+1) -> 2808 | J8: =MAX(MAX(Minors!B8:LS8),-MIN(Minors!B8:LS8)) -> 2192822252
A9: 8 | B9: 1-2-4-6 | C9: =COUNTIF(Minors!B9:LS9,">0") -> 160 | D9: =COUNTIF(Minors!B9:LS9,"<0") -> 170 | E9: =COUNTIF(Minors!B9:LS9,0) -> 0 | F9: =C9+D9 -> 330 | G9: =MIN(C9,D9) -> 160 | H9: =IF(F9=0,"rank<4",IF(G9=0,"YES","no")) -> no | I9: =MIN(MIN(Minors!B9:LS9),-MAX(Minors!B9:LS9))*0+SMALL(Minors!B9:LS9,COUNTIF(Minors!B9:LS9,"<0")+E9+1) -> 20 | J9: =MAX(MAX(Minors!B9:LS9),-MIN(Minors!B9:LS9)) -> 1305723720
A10: 9 | B10: 1-2-4-7 | C10: =COUNTIF(Minors!B10:LS10,">0") -> 172 | D10: =COUNTIF(Minors!B10:LS10,"<0") -> 158 | E10: =COUNTIF(Minors!B10:LS10,0) -> 0 | F10: =C10+D10 -> 330 | G10: =MIN(C10,D10) -> 158 | H10: =IF(F10=0,"rank<4",IF(G10=0,"YES","no")) -> no | I10: =MIN(MIN(Minors!B10:LS10),-MAX(Minors!B10:LS10))*0+SMALL(Minors!B10:LS10,COUNTIF(Minors!B10:LS10,"<0")+E10+1) -> 1266 | J10: =MAX(MAX(Minors!B10:LS10),-MIN(Minors!B10:LS10)) -> 2343600688
A11: 10 | B11: 1-2-4-8 | C11: =COUNTIF(Minors!B11:LS11,">0") -> 153 | D11: =COUNTIF(Minors!B11:LS11,"<0") -> 177 | E11: =COUNTIF(Minors!B11:LS11,0) -> 0 | F11: =C11+D11 -> 330 | G11: =MIN(C11,D11) -> 153 | H11: =IF(F11=0,"rank<4",IF(G11=0,"YES","no")) -> no | I11: =MIN(MIN(Minors!B11:LS11),-MAX(Minors!B11:LS11))*0+SMALL(Minors!B11:LS11,COUNTIF(Minors!B11:LS11,"<0")+E11+1) -> 182 | J11: =MAX(MAX(Minors!B11:LS11),-MIN(Minors!B11:LS11)) -> 5593483074
A12: 11 | B12: 1-2-4-9 | C12: =COUNTIF(Minors!B12:LS12,">0") -> 147 | D12: =COUNTIF(Minors!B12:LS12,"<0") -> 183 | E12: =COUNTIF(Minors!B12:LS12,0) -> 0 | F12: =C12+D12 -> 330 | G12: =MIN(C12,D12) -> 147 | H12: =IF(F12=0,"rank<4",IF(G12=0,"YES","no")) -> no | I12: =MIN(MIN(Minors!B12:LS12),-MAX(Minors!B12:LS12))*0+SMALL(Minors!B12:LS12,COUNTIF(Minors!B12:LS12,"<0")+E12+1) -> 165 | J12: =MAX(MAX(Minors!B12:LS12),-MIN(Minors!B12:LS12)) -> 3173550624
A13: 12 | B13: 1-2-5-6 | C13: =COUNTIF(Minors!B13:LS13,">0") -> 176 | D13: =COUNTIF(Minors!B13:LS13,"<0") -> 154 | E13: =COUNTIF(Minors!B13:LS13,0) -> 0 | F13: =C13+D13 -> 330 | G13: =MIN(C13,D13) -> 154 | H13: =IF(F13=0,"rank<4",IF(G13=0,"YES","no")) -> no | I13: =MIN(MIN(Minors!B13:LS13),-MAX(Minors!B13:LS13))*0+SMALL(Minors!B13:LS13,COUNTIF(Minors!B13:LS13,"<0")+E13+1) -> 308 | J13: =MAX(MAX(Minors!B13:LS13),-MIN(Minors!B13:LS13)) -> 4619250542
... A127: 126 | B127: 6-7-8-9 | C127: =COUNTIF(Minors!B127:LS127,">0") -> 152 | D127: =COUNTIF(Minors!B127:LS127,"<0") -> 178 | E127: =COUNTIF(Minors!B127:LS127,0) -> 0 | F127: =C127+D127 -> 330 | G127: =MIN(C127,D127) -> 152 | H127: =IF(F127=0,"rank<4",IF(G127=0,"YES","no")) -> no | I127: =MIN(MIN(Minors!B127:LS127),-MAX(Minors!B127:LS127))*0+SMALL(Minors!B127:LS127,COUNTIF(Minors!B127:LS127,"<0")+E127+1) -> 650 | J127: =MAX(MAX(Minors!B127:LS127),-MIN(Minors!B127:LS127)) -> 6420364720
B129: Totals | C129: =SUM(C2:C127) -> 20720 | D129: =SUM(D2:D127) -> 20859 | E129: =SUM(E2:E127) -> 1
B130: Choices in Gr>=0 | C130: =COUNTIF(H2:H127,"YES") -> 0

Sheet Z_Grey
A1: Grey (62 cells, 114 names)
A2: Row \ D | B2: D1 | C2: D2 | D2: D3 | E2: D4 | F2: D5 | G2: D6 | H2: D7 | I2: D8 | J2: D9 | K2: D10 | L2: D11 | M2: Row total
A3: Row 1 (grid col 1) | B3: 839 | C3: 0 | D3: 0 | E3: 0 | F3: 0 | G3: 0 | H3: 217 | I3: 0 | J3: 271 | K3: 0 | L3: 0 | M3: =SUM(B3:L3) -> 1327
A4: Row 2 (grid col 2) | B4: 1321 | C4: 0 | D4: 0 | E4: 0 | F4: 191 | G4: 0 | H4: 0 | I4: 0 | J4: 0 | K4: 0 | L4: 0 | M4: =SUM(B4:L4) -> 1512
A5: Row 3 (grid col 3) | B5: 414 | C5: 0 | D5: 0 | E5: 0 | F5: 0 | G5: 0 | H5: 0 | I5: 0 | J5: 0 | K5: 0 | L5: 0 | M5: =SUM(B5:L5) -> 414
A6: Row 4 (grid col 4) | B6: 1002 | C6: 0 | D6: 0 | E6: 0 | F6: 0 | G6: 0 | H6: 211 | I6: 0 | J6: 0 | K6: 0 | L6: 0 | M6: =SUM(B6:L6) -> 1213
A7: Row 5 (grid col 5) | B7: 1132 | C7: 0 | D7: 0 | E7: 0 | F7: 0 | G7: 0 | H7: 0 | I7: 0 | J7: 0 | K7: 0 | L7: 0 | M7: =SUM(B7:L7) -> 1132
A8: Row 6 (grid col 6) | B8: 1239 | C8: 0 | D8: 0 | E8: 0 | F8: 186 | G8: 0 | H8: 0 | I8: 0 | J8: 0 | K8: 0 | L8: 0 | M8: =SUM(B8:L8) -> 1425
A9: Row 7 (grid col 7) | B9: 874 | C9: 0 | D9: 0 | E9: 0 | F9: 0 | G9: 0 | H9: 0 | I9: 0 | J9: 0 | K9: 0 | L9: 0 | M9: =SUM(B9:L9) -> 874
A10: Row 8 (grid col 8) | B10: 693 | C10: 0 | D10: 0 | E10: 0 | F10: 188 | G10: 0 | H10: 0 | I10: 0 | J10: 0 | K10: 0 | L10: 0 | M10: =SUM(B10:L10) -> 881
A11: Row 9 (grid col 9) | B11: 549 | C11: 0 | D11: 171 | E11: 0 | F11: 0 | G11: 0 | H11: 0 | I11: 0 | J11: 0 | K11: 0 | L11: 297 | M11: =SUM(B11:L11) -> 1017
A12: Column total | B12: =SUM(B3:B11) -> 8063 | C12: =SUM(C3:C11) -> 0 | D12: =SUM(D3:D11) -> 171 | E12: =SUM(E3:E11) -> 0 | F12: =SUM(F3:F11) -> 565 | G12: =SUM(G3:G11) -> 0 | H12: =SUM(H3:H11) -> 428 | I12: =SUM(I3:I11) -> 0 | ... M12: =SUM(M3:M11) -> 9795

Sheet Z_White
A1: White (99 static)
A2: Row \ D | B2: D1 | C2: D2 | D2: D3 | E2: D4 | F2: D5 | G2: D6 | H2: D7 | I2: D8 | J2: D9 | K2: D10 | L2: D11 | M2: Row total
A3: Row 1 (grid col 1) | B3: 329 | C3: 0 | D3: 60 | E3: 0 | F3: 144 | G3: 0 | H3: 191 | I3: 0 | J3: 0 | K3: 0 | L3: 56 | M3: =SUM(B3:L3) -> 780
A4: Row 2 (grid col 2) | B4: 235 | C4: 0 | D4: 61 | E4: 0 | F4: 65 | G4: 0 | H4: 151 | I4: 0 | J4: 56 | K4: 0 | L4: 56 | M4: =SUM(B4:L4) -> 624
A5: Row 3 (grid col 3) | B5: 624 | C5: 0 | D5: 85 | E5: 0 | F5: 99 | G5: 0 | H5: 300 | I5: 0 | J5: 66 | K5: 0 | L5: 79 | M5: =SUM(B5:L5) -> 1253
A6: Row 4 (grid col 4) | B6: 288 | C6: 0 | D6: 61 | E6: 0 | F6: 162 | G6: 0 | H6: 85 | I6: 0 | J6: 188 | K6: 0 | L6: 95 | M6: =SUM(B6:L6) -> 879
A7: Row 5 (grid col 5) | B7: 291 | C7: 0 | D7: 79 | E7: 0 | F7: 109 | G7: 0 | H7: 159 | I7: 0 | J7: 58 | K7: 0 | L7: 121 | M7: =SUM(B7:L7) -> 817
A8: Row 6 (grid col 6) | B8: 212 | C8: 0 | D8: 63 | E8: 0 | F8: 69 | G8: 0 | H8: 197 | I8: 0 | J8: 118 | K8: 0 | L8: 92 | M8: =SUM(B8:L8) -> 751
A9: Row 7 (grid col 7) | B9: 526 | C9: 0 | D9: 60 | E9: 0 | F9: 169 | G9: 0 | H9: 265 | I9: 0 | J9: 68 | K9: 0 | L9: 63 | M9: =SUM(B9:L9) -> 1151
A10: Row 8 (grid col 8) | B10: 268 | C10: 0 | D10: 78 | E10: 0 | F10: 100 | G10: 0 | H10: 256 | I10: 0 | J10: 94 | K10: 0 | L10: 105 | M10: =SUM(B10:L10) -> 901
A11: Row 9 (grid col 9) | B11: 389 | C11: 0 | D11: 0 | E11: 0 | F11: 157 | G11: 0 | H11: 44 | I11: 0 | J11: 94 | K11: 0 | L11: 0 | M11: =SUM(B11:L11) -> 684
A12: Column total | B12: =SUM(B3:B11) -> 3162 | C12: =SUM(C3:C11) -> 0 | D12: =SUM(D3:D11) -> 547 | E12: =SUM(E3:E11) -> 0 | F12: =SUM(F3:F11) -> 1074 | G12: =SUM(G3:G11) -> 0 | H12: =SUM(H3:H11) -> 1648 | I12: =SUM(I3:I11) -> 0 | ... M12: =SUM(M3:M11) -> 7840

Sheet Z_S3
A1: S3 (216 point)
A2: Row \ D | B2: D1 | C2: D2 | D2: D3 | E2: D4 | F2: D5 | G2: D6 | H2: D7 | I2: D8 | J2: D9 | K2: D10 | L2: D11 | M2: Row total
A3: Row 1 (grid col 1) | B3: 0 | C3: 0 | D3: 0 | E3: 0 | F3: 0 | G3: 0 | H3: 0 | I3: 0 | J3: 0 | K3: 0 | L3: 0 | M3: =SUM(B3:L3) -> 0
A4: Row 2 (grid col 2) | B4: 0 | C4: 0 | D4: 0 | E4: 0 | F4: 0 | G4: 0 | H4: 0 | I4: 0 | J4: 0 | K4: 0 | L4: 0 | M4: =SUM(B4:L4) -> 0
A5: Row 3 (grid col 3) | B5: 0 | C5: 0 | D5: 0 | E5: 0 | F5: 0 | G5: 0 | H5: 0 | I5: 0 | J5: 0 | K5: 0 | L5: 0 | M5: =SUM(B5:L5) -> 0
A6: Row 4 (grid col 4) | B6: 0 | C6: 0 | D6: 0 | E6: 0 | F6: 0 | G6: 0 | H6: 0 | I6: 0 | J6: 0 | K6: 0 | L6: 0 | M6: =SUM(B6:L6) -> 0
A7: Row 5 (grid col 5) | B7: 0 | C7: 0 | D7: 0 | E7: 0 | F7: 0 | G7: 0 | H7: 0 | I7: 0 | J7: 0 | K7: 0 | L7: 0 | M7: =SUM(B7:L7) -> 0
A8: Row 6 (grid col 6) | B8: 0 | C8: 0 | D8: 0 | E8: 0 | F8: 0 | G8: 0 | H8: 0 | I8: 0 | J8: 0 | K8: 0 | L8: 0 | M8: =SUM(B8:L8) -> 0
A9: Row 7 (grid col 7) | B9: 0 | C9: 0 | D9: 0 | E9: 0 | F9: 0 | G9: 0 | H9: 0 | I9: 0 | J9: 0 | K9: 0 | L9: 0 | M9: =SUM(B9:L9) -> 0
A10: Row 8 (grid col 8) | B10: 0 | C10: 0 | D10: 0 | E10: 0 | F10: 0 | G10: 0 | H10: 0 | I10: 0 | J10: 0 | K10: 0 | L10: 0 | M10: =SUM(B10:L10) -> 0
A11: Row 9 (grid col 9) | B11: 0 | C11: 0 | D11: 0 | E11: 0 | F11: 0 | G11: 0 | H11: 216 | I11: 0 | J11: 0 | K11: 0 | L11: 0 | M11: =SUM(B11:L11) -> 216
A12: Column total | B12: =SUM(B3:B11) -> 0 | C12: =SUM(C3:C11) -> 0 | D12: =SUM(D3:D11) -> 0 | E12: =SUM(E3:E11) -> 0 | F12: =SUM(F3:F11) -> 0 | G12: =SUM(G3:G11) -> 0 | H12: =SUM(H3:H11) -> 216 | I12: =SUM(I3:I11) -> 0 | ... M12: =SUM(M3:M11) -> 216

Sheet Z_Blue
A1: Blue (99 dynamic)
A2: Row \ D | B2: D1 | C2: D2 | D2: D3 | E2: D4 | F2: D5 | G2: D6 | H2: D7 | I2: D8 | J2: D9 | K2: D10 | L2: D11 | M2: Row total
A3: Row 1 (grid col 1) | B3: 0 | C3: 164 | D3: 0 | E3: 63 | F3: 0 | G3: 65 | H3: 0 | I3: 439 | J3: 0 | K3: 121 | L3: 0 | M3: =SUM(B3:L3) -> 852
A4: Row 2 (grid col 2) | B4: 0 | C4: 165 | D4: 0 | E4: 63 | F4: 0 | G4: 66 | H4: 0 | I4: 446 | J4: 0 | K4: 123 | L4: 0 | M4: =SUM(B4:L4) -> 863
A5: Row 3 (grid col 3) | B5: 0 | C5: 166 | D5: 0 | E5: 63 | F5: 0 | G5: 66 | H5: 0 | I5: 451 | J5: 0 | K5: 134 | L5: 0 | M5: =SUM(B5:L5) -> 880
A6: Row 4 (grid col 4) | B6: 0 | C6: 170 | D6: 0 | E6: 64 | F6: 0 | G6: 66 | H6: 0 | I6: 454 | J6: 0 | K6: 171 | L6: 0 | M6: =SUM(B6:L6) -> 925
A7: Row 5 (grid col 5) | B7: 0 | C7: 171 | D7: 0 | E7: 64 | F7: 0 | G7: 67 | H7: 0 | I7: 459 | J7: 0 | K7: 186 | L7: 0 | M7: =SUM(B7:L7) -> 947
A8: Row 6 (grid col 6) | B8: 0 | C8: 173 | D8: 0 | E8: 65 | F8: 0 | G8: 68 | H8: 0 | I8: 460 | J8: 0 | K8: 188 | L8: 0 | M8: =SUM(B8:L8) -> 954
A9: Row 7 (grid col 7) | B9: 0 | C9: 174 | D9: 0 | E9: 65 | F9: 0 | G9: 68 | H9: 0 | I9: 465 | J9: 0 | K9: 211 | L9: 0 | M9: =SUM(B9:L9) -> 983
A10: Row 8 (grid col 8) | B10: 0 | C10: 178 | D10: 0 | E10: 65 | F10: 0 | G10: 69 | H10: 0 | I10: 478 | J10: 0 | K10: 271 | L10: 0 | M10: =SUM(B10:L10) -> 1061
A11: Row 9 (grid col 9) | B11: 0 | C11: 181 | D11: 0 | E11: 65 | F11: 0 | G11: 69 | H11: 0 | I11: 483 | J11: 0 | K11: 297 | L11: 0 | M11: =SUM(B11:L11) -> 1095
A12: Column total | B12: =SUM(B3:B11) -> 0 | C12: =SUM(C3:C11) -> 1542 | D12: =SUM(D3:D11) -> 0 | E12: =SUM(E3:E11) -> 577 | F12: =SUM(F3:F11) -> 0 | G12: =SUM(G3:G11) -> 604 | H12: =SUM(H3:H11) -> 0 | I12: =SUM(I3:I11) -> 4135 | ... M12: =SUM(M3:M11) -> 8560

Sheet Total
A1: Total 9x11 matrix = Grey + White + S3 + Blue (formulas)
A2: Row \ D | B2: D1 | C2: D2 | D2: D3 | E2: D4 | F2: D5 | G2: D6 | H2: D7 | I2: D8 | J2: D9 | K2: D10 | L2: D11 | M2: Row total
A3: Row 1 (grid col 1) | B3: =Z_Grey!B3+Z_White!B3+Z_S3!B3+Z_Blue!B3 -> 1168 | C3: =Z_Grey!C3+Z_White!C3+Z_S3!C3+Z_Blue!C3 -> 164 | D3: =Z_Grey!D3+Z_White!D3+Z_S3!D3+Z_Blue!D3 -> 60 | E3: =Z_Grey!E3+Z_White!E3+Z_S3!E3+Z_Blue!E3 -> 63 | F3: =Z_Grey!F3+Z_White!F3+Z_S3!F3+Z_Blue!F3 -> 144 | G3: =Z_Grey!G3+Z_White!G3+Z_S3!G3+Z_Blue!G3 -> 65 | H3: =Z_Grey!H3+Z_White!H3+Z_S3!H3+Z_Blue!H3 -> 408 | I3: =Z_Grey!I3+Z_White!I3+Z_S3!I3+Z_Blue!I3 -> 439 | ... L3: =Z_Grey!L3+Z_White!L3+Z_S3!L3+Z_Blue!L3 -> 56 | M3: =SUM(B3:L3) -> 2959
A4: Row 2 (grid col 2) | B4: =Z_Grey!B4+Z_White!B4+Z_S3!B4+Z_Blue!B4 -> 1556 | C4: =Z_Grey!C4+Z_White!C4+Z_S3!C4+Z_Blue!C4 -> 165 | D4: =Z_Grey!D4+Z_White!D4+Z_S3!D4+Z_Blue!D4 -> 61 | E4: =Z_Grey!E4+Z_White!E4+Z_S3!E4+Z_Blue!E4 -> 63 | F4: =Z_Grey!F4+Z_White!F4+Z_S3!F4+Z_Blue!F4 -> 256 | G4: =Z_Grey!G4+Z_White!G4+Z_S3!G4+Z_Blue!G4 -> 66 | H4: =Z_Grey!H4+Z_White!H4+Z_S3!H4+Z_Blue!H4 -> 151 | I4: =Z_Grey!I4+Z_White!I4+Z_S3!I4+Z_Blue!I4 -> 446 | ... L4: =Z_Grey!L4+Z_White!L4+Z_S3!L4+Z_Blue!L4 -> 56 | M4: =SUM(B4:L4) -> 2999
A5: Row 3 (grid col 3) | B5: =Z_Grey!B5+Z_White!B5+Z_S3!B5+Z_Blue!B5 -> 1038 | C5: =Z_Grey!C5+Z_White!C5+Z_S3!C5+Z_Blue!C5 -> 166 | D5: =Z_Grey!D5+Z_White!D5+Z_S3!D5+Z_Blue!D5 -> 85 | E5: =Z_Grey!E5+Z_White!E5+Z_S3!E5+Z_Blue!E5 -> 63 | F5: =Z_Grey!F5+Z_White!F5+Z_S3!F5+Z_Blue!F5 -> 99 | G5: =Z_Grey!G5+Z_White!G5+Z_S3!G5+Z_Blue!G5 -> 66 | H5: =Z_Grey!H5+Z_White!H5+Z_S3!H5+Z_Blue!H5 -> 300 | I5: =Z_Grey!I5+Z_White!I5+Z_S3!I5+Z_Blue!I5 -> 451 | ... L5: =Z_Grey!L5+Z_White!L5+Z_S3!L5+Z_Blue!L5 -> 79 | M5: =SUM(B5:L5) -> 2547
A6: Row 4 (grid col 4) | B6: =Z_Grey!B6+Z_White!B6+Z_S3!B6+Z_Blue!B6 -> 1290 | C6: =Z_Grey!C6+Z_White!C6+Z_S3!C6+Z_Blue!C6 -> 170 | D6: =Z_Grey!D6+Z_White!D6+Z_S3!D6+Z_Blue!D6 -> 61 | E6: =Z_Grey!E6+Z_White!E6+Z_S3!E6+Z_Blue!E6 -> 64 | F6: =Z_Grey!F6+Z_White!F6+Z_S3!F6+Z_Blue!F6 -> 162 | G6: =Z_Grey!G6+Z_White!G6+Z_S3!G6+Z_Blue!G6 -> 66 | H6: =Z_Grey!H6+Z_White!H6+Z_S3!H6+Z_Blue!H6 -> 296 | I6: =Z_Grey!I6+Z_White!I6+Z_S3!I6+Z_Blue!I6 -> 454 | ... L6: =Z_Grey!L6+Z_White!L6+Z_S3!L6+Z_Blue!L6 -> 95 | M6: =SUM(B6:L6) -> 3017
A7: Row 5 (grid col 5) | B7: =Z_Grey!B7+Z_White!B7+Z_S3!B7+Z_Blue!B7 -> 1423 | C7: =Z_Grey!C7+Z_White!C7+Z_S3!C7+Z_Blue!C7 -> 171 | D7: =Z_Grey!D7+Z_White!D7+Z_S3!D7+Z_Blue!D7 -> 79 | E7: =Z_Grey!E7+Z_White!E7+Z_S3!E7+Z_Blue!E7 -> 64 | F7: =Z_Grey!F7+Z_White!F7+Z_S3!F7+Z_Blue!F7 -> 109 | G7: =Z_Grey!G7+Z_White!G7+Z_S3!G7+Z_Blue!G7 -> 67 | H7: =Z_Grey!H7+Z_White!H7+Z_S3!H7+Z_Blue!H7 -> 159 | I7: =Z_Grey!I7+Z_White!I7+Z_S3!I7+Z_Blue!I7 -> 459 | ... L7: =Z_Grey!L7+Z_White!L7+Z_S3!L7+Z_Blue!L7 -> 121 | M7: =SUM(B7:L7) -> 2896
A8: Row 6 (grid col 6) | B8: =Z_Grey!B8+Z_White!B8+Z_S3!B8+Z_Blue!B8 -> 1451 | C8: =Z_Grey!C8+Z_White!C8+Z_S3!C8+Z_Blue!C8 -> 173 | D8: =Z_Grey!D8+Z_White!D8+Z_S3!D8+Z_Blue!D8 -> 63 | E8: =Z_Grey!E8+Z_White!E8+Z_S3!E8+Z_Blue!E8 -> 65 | F8: =Z_Grey!F8+Z_White!F8+Z_S3!F8+Z_Blue!F8 -> 255 | G8: =Z_Grey!G8+Z_White!G8+Z_S3!G8+Z_Blue!G8 -> 68 | H8: =Z_Grey!H8+Z_White!H8+Z_S3!H8+Z_Blue!H8 -> 197 | I8: =Z_Grey!I8+Z_White!I8+Z_S3!I8+Z_Blue!I8 -> 460 | ... L8: =Z_Grey!L8+Z_White!L8+Z_S3!L8+Z_Blue!L8 -> 92 | M8: =SUM(B8:L8) -> 3130
A9: Row 7 (grid col 7) | B9: =Z_Grey!B9+Z_White!B9+Z_S3!B9+Z_Blue!B9 -> 1400 | C9: =Z_Grey!C9+Z_White!C9+Z_S3!C9+Z_Blue!C9 -> 174 | D9: =Z_Grey!D9+Z_White!D9+Z_S3!D9+Z_Blue!D9 -> 60 | E9: =Z_Grey!E9+Z_White!E9+Z_S3!E9+Z_Blue!E9 -> 65 | F9: =Z_Grey!F9+Z_White!F9+Z_S3!F9+Z_Blue!F9 -> 169 | G9: =Z_Grey!G9+Z_White!G9+Z_S3!G9+Z_Blue!G9 -> 68 | H9: =Z_Grey!H9+Z_White!H9+Z_S3!H9+Z_Blue!H9 -> 265 | I9: =Z_Grey!I9+Z_White!I9+Z_S3!I9+Z_Blue!I9 -> 465 | ... L9: =Z_Grey!L9+Z_White!L9+Z_S3!L9+Z_Blue!L9 -> 63 | M9: =SUM(B9:L9) -> 3008
A10: Row 8 (grid col 8) | B10: =Z_Grey!B10+Z_White!B10+Z_S3!B10+Z_Blue!B10 -> 961 | C10: =Z_Grey!C10+Z_White!C10+Z_S3!C10+Z_Blue!C10 -> 178 | D10: =Z_Grey!D10+Z_White!D10+Z_S3!D10+Z_Blue!D10 -> 78 | E10: =Z_Grey!E10+Z_White!E10+Z_S3!E10+Z_Blue!E10 -> 65 | F10: =Z_Grey!F10+Z_White!F10+Z_S3!F10+Z_Blue!F10 -> 288 | G10: =Z_Grey!G10+Z_White!G10+Z_S3!G10+Z_Blue!G10 -> 69 | H10: =Z_Grey!H10+Z_White!H10+Z_S3!H10+Z_Blue!H10 -> 256 | I10: =Z_Grey!I10+Z_White!I10+Z_S3!I10+Z_Blue!I10 -> 478 | ... L10: =Z_Grey!L10+Z_White!L10+Z_S3!L10+Z_Blue!L10 -> 105 | M10: =SUM(B10:L10) -> 2843
A11: Row 9 (grid col 9) | B11: =Z_Grey!B11+Z_White!B11+Z_S3!B11+Z_Blue!B11 -> 938 | C11: =Z_Grey!C11+Z_White!C11+Z_S3!C11+Z_Blue!C11 -> 181 | D11: =Z_Grey!D11+Z_White!D11+Z_S3!D11+Z_Blue!D11 -> 171 | E11: =Z_Grey!E11+Z_White!E11+Z_S3!E11+Z_Blue!E11 -> 65 | F11: =Z_Grey!F11+Z_White!F11+Z_S3!F11+Z_Blue!F11 -> 157 | G11: =Z_Grey!G11+Z_White!G11+Z_S3!G11+Z_Blue!G11 -> 69 | H11: =Z_Grey!H11+Z_White!H11+Z_S3!H11+Z_Blue!H11 -> 260 | I11: =Z_Grey!I11+Z_White!I11+Z_S3!I11+Z_Blue!I11 -> 483 | ... L11: =Z_Grey!L11+Z_White!L11+Z_S3!L11+Z_Blue!L11 -> 297 | M11: =SUM(B11:L11) -> 3012
A12: Column total | B12: =SUM(B3:B11) -> 11225 | C12: =SUM(C3:C11) -> 1542 | D12: =SUM(D3:D11) -> 718 | E12: =SUM(E3:E11) -> 577 | F12: =SUM(F3:F11) -> 1639 | G12: =SUM(G3:G11) -> 604 | H12: =SUM(H3:H11) -> 2292 | I12: =SUM(I3:I11) -> 4135 | ... M12: =SUM(M3:M11) -> 26411

Sheet Minors
A1: Choice of 4 rows \ columns D | B1: D1-D2-D3-D4 | C1: D1-D2-D3-D5 | D1: D1-D2-D3-D6 | E1: D1-D2-D3-D7 | F1: D1-D2-D3-D8 | G1: D1-D2-D3-D9 | H1: D1-D2-D3-D10 | I1: D1-D2-D3-D11 | J1: D1-D2-D4-D5 | K1: D1-D2-D4-D6 | L1: D1-D2-D4-D7 | M1: D1-D2-D4-D8 | N1: D1-D2-D4-D9 | O1: D1-D2-D4-D10 | P1: D1-D2-D4-D11 | Q1: D1-D2-D5-D6 | R1: D1-D2-D5-D7 | S1: D1-D2-D5-D8 | T1: D1-D2-D5-D9 | U1: D1-D2-D5-D10 | V1: D1-D2-D5-D11 | W1: D1-D2-D6-D7 | X1: D1-D2-D6-D8 | Y1: D1-D2-D6-D9 | Z1: D1-D2-D6-D10 | AA1: D1-D2-D6-D11 | AB1: D1-D2-D7-D8 | AC1: D1-D2-D7-D9 | AD1: D1-D2-D7-D10 | AE1: D1-D2-D7-D11 | AF1: D1-D2-D8-D9 | AG1: D1-D2-D8-D10 | AH1: D1-D2-D8-D11 | AI1: D1-D2-D9-D10 | AJ1: D1-D2-D9-D11 | AK1: D1-D2-D10-D11 | AL1: D1-D3-D4-D5 | AM1: D1-D3-D4-D6 | AN1: D1-D3-D4-D7 | AO1: D1-D3-D4-D8 | AP1: D1-D3-D4-D9 | AQ1: D1-D3-D4-D10 | AR1: D1-D3-D4-D11 | AS1: D1-D3-D5-D6 | AT1: D1-D3-D5-D7 | AU1: D1-D3-D5-D8 | AV1: D1-D3-D5-D9 | AW1: D1-D3-D5-D10 | AX1: D1-D3-D5-D11 | AY1: D1-D3-D6-D7 | AZ1: D1-D3-D6-D8 | BA1: D1-D3-D6-D9 | BB1: D1-D3-D6-D10 | BC1: D1-D3-D6-D11 | BD1: D1-D3-D7-D8 | BE1: D1-D3-D7-D9 | BF1: D1-D3-D7-D10 | BG1: D1-D3-D7-D11 | BH1: D1-D3-D8-D9 | BI1: D1-D3-D8-D10 | BJ1: D1-D3-D8-D11 | BK1: D1-D3-D9-D10 | BL1: D1-D3-D9-D11 | BM1: D1-D3-D10-D11 | BN1: D1-D4-D5-D6 | BO1: D1-D4-D5-D7 | BP1: D1-D4-D5-D8 | BQ1: D1-D4-D5-D9 | BR1: D1-D4-D5-D10 | BS1: D1-D4-D5-D11 | BT1: D1-D4-D6-D7 | BU1: D1-D4-D6-D8 | BV1: D1-D4-D6-D9 | BW1: D1-D4-D6-D10 | BX1: D1-D4-D6-D11 | BY1: D1-D4-D7-D8 | BZ1: D1-D4-D7-D9 | CA1: D1-D4-D7-D10 | CB1: D1-D4-D7-D11 | CC1: D1-D4-D8-D9 | CD1: D1-D4-D8-D10 | CE1: D1-D4-D8-D11 | CF1: D1-D4-D9-D10 | CG1: D1-D4-D9-D11 | CH1: D1-D4-D10-D11 | CI1: D1-D5-D6-D7 | CJ1: D1-D5-D6-D8 | CK1: D1-D5-D6-D9 | CL1: D1-D5-D6-D10 | CM1: D1-D5-D6-D11 | CN1: D1-D5-D7-D8 | CO1: D1-D5-D7-D9 | CP1: D1-D5-D7-D10 | CQ1: D1-D5-D7-D11 | CR1: D1-D5-D8-D9 | CS1: D1-D5-D8-D10 | CT1: D1-D5-D8-D11 | CU1: D1-D5-D9-D10 | CV1: D1-D5-D9-D11 | CW1: D1-D5-D10-D11 | CX1: D1-D6-D7-D8 | CY1: D1-D6-D7-D9 | CZ1: D1-D6-D7-D10 | DA1: D1-D6-D7-D11 | DB1: D1-D6-D8-D9 | DC1: D1-D6-D8-D10 | DD1: D1-D6-D8-D11 | DE1: D1-D6-D9-D10 | DF1: D1-D6-D9-D11 | DG1: D1-D6-D10-D11 | DH1: D1-D7-D8-D9 | DI1: D1-D7-D8-D10 | DJ1: D1-D7-D8-D11 | DK1: D1-D7-D9-D10 | DL1: D1-D7-D9-D11 | DM1: D1-D7-D10-D11 | DN1: D1-D8-D9-D10 | DO1: D1-D8-D9-D11 | DP1: D1-D8-D10-D11 | DQ1: D1-D9-D10-D11 | DR1: D2-D3-D4-D5 | DS1: D2-D3-D4-D6 | DT1: D2-D3-D4-D7 | DU1: D2-D3-D4-D8 | DV1: D2-D3-D4-D9 | DW1: D2-D3-D4-D10 | DX1: D2-D3-D4-D11 | DY1: D2-D3-D5-D6 | DZ1: D2-D3-D5-D7 | EA1: D2-D3-D5-D8 | EB1: D2-D3-D5-D9 | EC1: D2-D3-D5-D10 | ED1: D2-D3-D5-D11 | EE1: D2-D3-D6-D7 | EF1: D2-D3-D6-D8 | EG1: D2-D3-D6-D9 | EH1: D2-D3-D6-D10 | EI1: D2-D3-D6-D11 | EJ1: D2-D3-D7-D8 | EK1: D2-D3-D7-D9 | EL1: D2-D3-D7-D10 | EM1: D2-D3-D7-D11 | EN1: D2-D3-D8-D9 | EO1: D2-D3-D8-D10 | EP1: D2-D3-D8-D11 | EQ1: D2-D3-D9-D10 | ER1: D2-D3-D9-D11 | ES1: D2-D3-D10-D11 | ET1: D2-D4-D5-D6 | EU1: D2-D4-D5-D7 | EV1: D2-D4-D5-D8 | EW1: D2-D4-D5-D9 | EX1: D2-D4-D5-D10 | EY1: D2-D4-D5-D11 | EZ1: D2-D4-D6-D7 | FA1: D2-D4-D6-D8 | FB1: D2-D4-D6-D9 | FC1: D2-D4-D6-D10 | FD1: D2-D4-D6-D11 | FE1: D2-D4-D7-D8 | FF1: D2-D4-D7-D9 | FG1: D2-D4-D7-D10 | FH1: D2-D4-D7-D11 | FI1: D2-D4-D8-D9 | FJ1: D2-D4-D8-D10 | FK1: D2-D4-D8-D11 | FL1: D2-D4-D9-D10 | FM1: D2-D4-D9-D11 | FN1: D2-D4-D10-D11 | FO1: D2-D5-D6-D7 | FP1: D2-D5-D6-D8 | FQ1: D2-D5-D6-D9 | FR1: D2-D5-D6-D10 | FS1: D2-D5-D6-D11 | FT1: D2-D5-D7-D8 | FU1: D2-D5-D7-D9 | FV1: D2-D5-D7-D10 | FW1: D2-D5-D7-D11 | FX1: D2-D5-D8-D9 | FY1: D2-D5-D8-D10 | FZ1: D2-D5-D8-D11 | GA1: D2-D5-D9-D10 | GB1: D2-D5-D9-D11 | GC1: D2-D5-D10-D11 | GD1: D2-D6-D7-D8 | GE1: D2-D6-D7-D9 | GF1: D2-D6-D7-D10 | GG1: D2-D6-D7-D11 | GH1: D2-D6-D8-D9 | GI1: D2-D6-D8-D10 | GJ1: D2-D6-D8-D11 | GK1: D2-D6-D9-D10 | GL1: D2-D6-D9-D11 | GM1: D2-D6-D10-D11 | GN1: D2-D7-D8-D9 | GO1: D2-D7-D8-D10 | GP1: D2-D7-D8-D11 | GQ1: D2-D7-D9-D10 | GR1: D2-D7-D9-D11 | GS1: D2-D7-D10-D11 | GT1: D2-D8-D9-D10 | GU1: D2-D8-D9-D11 | GV1: D2-D8-D10-D11 | GW1: D2-D9-D10-D11 | GX1: D3-D4-D5-D6 | GY1: D3-D4-D5-D7 | GZ1: D3-D4-D5-D8 | HA1: D3-D4-D5-D9 | HB1: D3-D4-D5-D10 | HC1: D3-D4-D5-D11 | HD1: D3-D4-D6-D7 | HE1: D3-D4-D6-D8 | HF1: D3-D4-D6-D9 | HG1: D3-D4-D6-D10 | HH1: D3-D4-D6-D11 | HI1: D3-D4-D7-D8 | HJ1: D3-D4-D7-D9 | HK1: D3-D4-D7-D10 | HL1: D3-D4-D7-D11 | HM1: D3-D4-D8-D9 | HN1: D3-D4-D8-D10 | HO1: D3-D4-D8-D11 | HP1: D3-D4-D9-D10 | HQ1: D3-D4-D9-D11 | HR1: D3-D4-D10-D11 | HS1: D3-D5-D6-D7 | HT1: D3-D5-D6-D8 | HU1: D3-D5-D6-D9 | HV1: D3-D5-D6-D10 | HW1: D3-D5-D6-D11 | HX1: D3-D5-D7-D8 | HY1: D3-D5-D7-D9 | HZ1: D3-D5-D7-D10 | IA1: D3-D5-D7-D11 | IB1: D3-D5-D8-D9 | IC1: D3-D5-D8-D10 | ID1: D3-D5-D8-D11 | IE1: D3-D5-D9-D10 | IF1: D3-D5-D9-D11 | IG1: D3-D5-D10-D11 | IH1: D3-D6-D7-D8 | II1: D3-D6-D7-D9 | IJ1: D3-D6-D7-D10 | IK1: D3-D6-D7-D11 | IL1: D3-D6-D8-D9 | IM1: D3-D6-D8-D10 | IN1: D3-D6-D8-D11 | IO1: D3-D6-D9-D10 | IP1: D3-D6-D9-D11 | IQ1: D3-D6-D10-D11 | IR1: D3-D7-D8-D9 | IS1: D3-D7-D8-D10 | IT1: D3-D7-D8-D11 | IU1: D3-D7-D9-D10 | IV1: D3-D7-D9-D11 | IW1: D3-D7-D10-D11 | IX1: D3-D8-D9-D10 | IY1: D3-D8-D9-D11 | IZ1: D3-D8-D10-D11 | JA1: D3-D9-D10-D11 | JB1: D4-D5-D6-D7 | JC1: D4-D5-D6-D8 | JD1: D4-D5-D6-D9 | JE1: D4-D5-D6-D10 | JF1: D4-D5-D6-D11 | JG1: D4-D5-D7-D8 | JH1: D4-D5-D7-D9 | JI1: D4-D5-D7-D10 | JJ1: D4-D5-D7-D11 | JK1: D4-D5-D8-D9 | JL1: D4-D5-D8-D10 | JM1: D4-D5-D8-D11 | JN1: D4-D5-D9-D10 | JO1: D4-D5-D9-D11 | JP1: D4-D5-D10-D11 | JQ1: D4-D6-D7-D8 | JR1: D4-D6-D7-D9 | JS1: D4-D6-D7-D10 | JT1: D4-D6-D7-D11 | JU1: D4-D6-D8-D9 | JV1: D4-D6-D8-D10 | JW1: D4-D6-D8-D11 | JX1: D4-D6-D9-D10 | JY1: D4-D6-D9-D11 | JZ1: D4-D6-D10-D11 | KA1: D4-D7-D8-D9 | KB1: D4-D7-D8-D10 | KC1: D4-D7-D8-D11 | KD1: D4-D7-D9-D10 | KE1: D4-D7-D9-D11 | KF1: D4-D7-D10-D11 | KG1: D4-D8-D9-D10 | KH1: D4-D8-D9-D11 | KI1: D4-D8-D10-D11 | KJ1: D4-D9-D10-D11 | KK1: D5-D6-D7-D8 | KL1: D5-D6-D7-D9 | KM1: D5-D6-D7-D10 | KN1: D5-D6-D7-D11 | KO1: D5-D6-D8-D9 | KP1: D5-D6-D8-D10 | KQ1: D5-D6-D8-D11 | KR1: D5-D6-D9-D10 | KS1: D5-D6-D9-D11 | KT1: D5-D6-D10-D11 | KU1: D5-D7-D8-D9 | KV1: D5-D7-D8-D10 | KW1: D5-D7-D8-D11 | KX1: D5-D7-D9-D10 | KY1: D5-D7-D9-D11 | KZ1: D5-D7-D10-D11 | LA1: D5-D8-D9-D10 | LB1: D5-D8-D9-D11 | LC1: D5-D8-D10-D11 | LD1: D5-D9-D10-D11 | LE1: D6-D7-D8-D9 | LF1: D6-D7-D8-D10 | LG1: D6-D7-D8-D11 | LH1: D6-D7-D9-D10 | LI1: D6-D7-D9-D11 | LJ1: D6-D7-D10-D11 | LK1: D6-D8-D9-D10 | LL1: D6-D8-D9-D11 | LM1: D6-D8-D10-D11 | LN1: D6-D9-D10-D11 | LO1: D7-D8-D9-D10 | LP1: D7-D8-D9-D11 | LQ1: D7-D8-D10-D11 | LR1: D7-D9-D10-D11 | LS1: D8-D9-D10-D11
A2: 1-2-3-4 | B2: 1950988 | C2: 16300976 | D2: 2265844 | E2: 129147952 | F2: 2314972 | G2: 97284236 | H2: -70360588 | I2: -58516544 | J2: -235802 | K2: -119182 | L2: 12001120 | M2: -745724 | N2: 19486410 | O2: 1667880 | P2: 415484 | Q2: -721938 | R2: 115881448 | S2: -5950910 | T2: 174571714 | U2: 5431558 | V2: -3601008 | W2: 21827288 | X2: -724654 | Y2: 28574084 | Z2: -2361142 | AA2: -3092124 | AB2: -63604176 | AC2: 691501000 | AD2: 543216640 | AE2: 387456496 | AF2: 60306718 | AG2: -24914804 | AH2: -21873716 | AI2: 785926770 | AJ2: 605179228 | AK2: 35041156 | AL2: -8803310 | AM2: -177646 | AN2: -31970972 | AO2: 3894848 | AP2: -20044470 | AQ2: 29517992 | AR2: 23724972 | AS2: 8739738 | AT2: 315620296 | AU2: 42988086 | AV2: 271492630 | AW2: -70853326 | AX2: -65812336 | AY2: -25371052 | AZ2: 4734198 | BA2: -14421148 | BB2: 27875050 | BC2: 22225588 | BD2: 295759660 | BE2: 267336004 | BF2: 800974596 | BG2: 611587952 | BH2: -217997086 | BI2: 175489096 | BJ2: 144970492 | BK2: 749002354 | BL2: 581824524 | BM2: 29722324 | BN2: -516306 | BO2: 58015938 | BP2: -3835622 | BQ2: 90349830 | BR2: 3958232 | BS2: -992708 | BT2: 3045798 | BU2: -305830 | BV2: 2998800 | BW2: -1651328 | BX2: -1411480 | BY2: 11738164 | BZ2: 196025490 | CA2: 208905800 | CB2: 152748076 | CC2: -31240050 | CD2: -14612296 | CE2: -9897820 | CF2: 311960640 | CG2: 241233000 | CH2: 13996064 | CI2: -76107822 | CJ2: 1286712 | CK2: -105620172 | CL2: 225834 | CM2: 4845372 | CN2: 420818338 | CO2: -1450061454 | CP2: -608852866 | CQ2: -398128160 | CR2: -559483804 | CS2: 11542222 | CT2: 33522148 | CU2: -849250654 | CV2: -644827964 | CW2: -37580996 | CX2: 37491314 | CY2: 181027476 | CZ2: 242087314 | DA2: 179480084 | DB2: -55089860 | DC2: -3981586 | DD2: -647500 | DE2: 336498736 | DF2: 260602160 | DG2: 14879816 | DH2: -1715255902 | DI2: -1638484348 | DJ2: -1188509356 | DK2: 3164226470 | DL2: 2472610708 | DM2: 169433132 | DN2: 2225433722 | DO2: 1716775940 | DP2: 97922244 | DQ2: 41022088 | DR2: -585253 | DS2: -5179 | DT2: 1178948 | DU2: -23238 | DV2: 979205 | DW2: 61722 | DX2: 60076 | DY2: 636431 | DZ2: 48591908 | EA2: 500281 | EB2: 37364601 | EC2: -20590909 | ED2: -17051712 | EE2: 1712040 | EF2: -20843 | EG2: 1395478 | EH2: -115093 | EI2: -85564 | EJ2: -2937164 | EK2: 6032464 | EL2: 46603436 | EM2: 39337328 | EN2: 2320631 | EO2: -764820 | EP2: -625700 | EQ2: 38391839 | ER2: 32365212 | ES2: -315340 | ET2: -35126 | EU2: 3457578 | EV2: -220892 | EW2: 5727140 | EX2: 492867 | EY2: 117375 | EZ2: -40162 | FA2: -560 | FB2: -8090 | FC2: 657 | FD2: -2567 | FE2: 307684 | FF2: -5751910 | FG2: -628200 | FH2: 118476 | FI2: -142180 | FJ2: -3726 | FK2: -18014 | FL2: -220635 | FM2: 391505 | FN2: 38214 | FO2: -6676342 | FP2: 210182 | FQ2: -8470522 | FR2: 699869 | FS2: 895779 | FT2: 21295618 | FU2: -254764414 | FV2: -162569046 | FW2: -110484012 | FX2: -18998144 | FY2: 7350317 | FZ2: 6335493 | GA2: -232963859 | GB2: -174357435 | GC2: -10230393 | GD2: 346754 | GE2: -8147284 | GF2: 675334 | GG2: 1512112 | GH2: -183450 | GI2: 15089 | GJ2: -1079 | GK2: 2756 | GL2: 825334 | GM2: -67901 | GN2: 12755618 | GO2: -10597588 | GP2: -10561492 | GQ2: 224156770 | GR2: 192527128 | GS2: 25644132 | GT2: 5051587 | GU2: 5627243 | GV2: -492560 | GW2: 22642343 | GX2: -29921 | GY2: -14910267 | GZ2: 1273223 | HA2: -10431295 | HB2: 8576237 | HC2: 6845887 | HD2: -192217 | HE2: 12455 | HF2: -142370 | HG2: 72737 | HH2: 57509 | HI2: -1972786 | HJ2: -3933775 | HK2: -18848650 | HL2: -15321056 | HM2: 1716085 | HN2: 474804 | HO2: 402518 | HP2: -15449275 | HQ2: -12524835 | HR2: 158366 | HS2: 13729853 | HT2: -1410138 | HU2: 9433208 | HV2: -8273486 | HW2: -6572765 | HX2: -118457587 | HY2: -85842619 | HZ2: -187474081 | IA2: -133974764 | IB2: 90203806 | IC2: -52126768 | ID2: -42948091 | IE2: -180533594 | IF2: -133143099 | IG2: -9015737 | IH2: -3343711 | II2: -4728994 | IJ2: -19773281 | IK2: -15835268 | IL2: 2783020 | IM2: 15944 | IN2: 25673 | IO2: -16435044 | IP2: -13143618 | IQ2: 76311 | IR2: 19894773 | IS2: 124942052 | IT2: 103994904 | IU2: 59055725 | IV2: 52861092 | IW2: 23276408 | IX2: -103896248 | IY2: -86403741 | IZ2: 463420 | JA2: 19574667 | JB2: -1071660 | JC2: 87710 | JD2: -918870 | JE2: 489535 | JF2: 404879 | JG2: -1894410 | JH2: -84281790 | JI2: -63223575 | JJ2: -43434687 | JK2: 8522360 | JL2: 4309165 | JM2: 2839193 | JN2: -92709565 | JO2: -69084185 | JP2: -4045218 | JQ2: 117370 | JR2: -803790 | JS2: 539675 | JT2: 541243 | JU2: -34850 | JV2: 9445 | JW2: 45 | JX2: 95560 | JY2: 160400 | JZ2: -43348 | KA2: -10651570 | KB2: -5970350 | KC2: -3800266 | KD2: 89863625 | KE2: 75144445 | KF2: 10057950 | KG2: 2629895 | KH2: 1132475 | KI2: -303526 | KJ2: 8999020 | KK2: 10258450 | KL2: 83779230 | KM2: 71692805 | KN2: 49625353 | KO2: -15652780 | KP2: -1181630 | KQ2: -185888 | KR2: 99741740 | KS2: 74202358 | KT2: 4417039 | KU2: -658686820 | KV2: -478472945 | KW2: -328053487 | KX2: 695720195 | KY2: 507240121 | KZ2: 21963759 | LA2: 654202890 | LB2: 488622266 | LC2: 29117017 | LD2: -12306949 | LE2: -16869910 | LF2: -2685885 | LG2: -254011 | LH2: 95962820 | LI2: 79533886 | LJ2: 11217799 | LK2: 2155060 | LL2: 81890 | LM2: -19411 | LN2: 9694296 | LO2: -614385065 | LP2: -523170567 | LQ2: -74043988 | LR2: 79460485 | LS2: 63850487
A3: 1-2-3-5 | B3: 1350157 | C3: 149919352 | D3: 2121599 | E3: -18522492 | F3: 9961681 | G3: -126809271 | H3: -78492405 | I3: -73820528 | J3: -5332187 | K3: -103117 | L3: 12328090 | M3: -827750 | N3: 20723415 | O3: 2265309 | P3: 1530017 | Q3: -3071103 | R3: 1295741068 | S3: -52570329 | T3: 1800287079 | U3: -58454331 | V3: -121649336 | W3: 17957378 | X3: -539889 | Y3: 22879254 | Z3: -2435142 | AA3: -3233749 | AB3: -79602970 | AC3: 873577530 | AD3: 685625646 | AE3: 653054708 | AF3: 75156945 | AG3: -31408053 | AH3: -33968939 | AI3: 992009448 | AJ3: 989361309 | AK3: 34908231 | AL3: -62175335 | AM3: -346864 | AN3: 21522517 | AO3: -686323 | AP3: 64660920 | AQ3: 32482583 | AR3: 29899413 | AS3: 59185341 | AT3: 1536858052 | AU3: 382531627 | AV3: 1340225115 | AW3: -7794487 | AX3: -79483672 | AY3: 29061335 | AZ3: 1480751 | BA3: 69028248 | BB3: 30877021 | BC3: 28018135 | BD3: -149381173 | BE3: 1134366831 | BF3: 805606857 | BG3: 766571540 | BH3: 412618191 | BI3: 199761944 | BJ3: 183077737 | BK3: 708286851 | BL3: 727160241 | BM3: 37776787 | BN3: -3378711 | BO3: 482715003 | BP3: -35407757 | BQ3: 698956605 | BR3: -23965258 | BS3: -47624048 | BT3: 1523403 | BU3: -160237 | BV3: 385560 | BW3: -1898855 | BX3: -1890469 | BY3: 6928240 | BZ3: 260062785 | CA3: 260483081 | CB3: 248617633 | CC3: -29107815 | CD3: -18762799 | CE3: -17552887 | CF3: 390082845 | CG3: 385648215 | CH3: 13355858 | CI3: -543016797 | CJ3: 12917604 | CK3: -738174042 | CL3: 23236341 | CM3: 49653096 | CN3: 3845101147 | CO3: -6871701069 | CP3: 531861773 | CQ3: 560084488 | CR3: -5063541234 | CS3: 151884255 | CT3: 338269880 | CU3: 428961621 | CV3: 133031976 | CW3: 24666400 | CX3: 19928507 | CY3: 270863946 | CZ3: 294701692 | DA3: 281443055 | DB3: -33534174 | DC3: -6157773 | DD3: -4872884 | DE3: 412206450 | DF3: 407359758 | DG3: 14904041 | DH3: -2170175985 | DI3: -2067263129 | DJ3: -1972342977 | DK3: 3994653798 | DL3: 3840947919 | DM3: 28303073 | DN3: 2808063363 | DO3: 2788260894 | DP3: 103956955 | DQ3: -162434679 | DR3: -536239 | DS3: -4108 | DT3: 918002 | DU3: -23994 | DV3: 861395 | DW3: 70920 | DX3: 73117 | DY3: 386485 | DZ3: 94576988 | EA3: 1292203 | EB3: 45283403 | EC3: -23299815 | ED3: -21200344 | EE3: 1386166 | EF3: -7394 | EG3: 967741 | EH3: -127380 | EI3: -109713 | EJ3: -6444002 | EK3: 74403186 | EL3: 52395810 | EM3: 49189156 | EN3: 4101953 | EO3: -871650 | EP3: -772415 | EQ3: 43416915 | ER3: 40229929 | ES3: -373125 | ET3: -24731 | EU3: 1270848 | EV3: -233996 | EW3: 4828760 | EX3: 619623 | EY3: 318912 | EZ3: -32602 | FA3: -686 | FB3: -2735 | FC3: 1476 | FD3: -929 | FE3: 343720 | FF3: -6225040 | FG3: -892674 | FH3: -372672 | FI3: -159820 | FJ3: -3222 | FK3: -17636 | FL3: -356715 | FM3: 146120 | FN3: 42309 | FO3: -5277772 | FP3: 109053 | FQ3: -5568687 | FR3: 627990 | FS3: 747896 | FT3: 44332528 | FU3: -744334624 | FV3: -164502396 | FW3: -106490112 | FX3: -31396212 | FY3: 8674089 | FZ3: 8482592 | GA3: -262136571 | GB3: -217837184 | GC3: -10640088 | GD3: 290158 | GE3: -6757334 | GF3: 512868 | GG3: 1184180 | GH3: -166527 | GI3: 23928 | GJ3: 16649 | GK3: -262902 | GL3: 291893 | GM3: -68226 | GN3: 15839080 | GO3: -13351926 | GP3: -15801488 | GQ3: 282949518 | GR3: 303350624 | GS3: 26561412 | GT3: 6356739 | GU3: 8159932 | GV3: -536955 | GW3: 24024633 | GX3: 51412 | GY3: -33726351 | GZ3: 832349 | HA3: -13986385 | HB3: 9635141 | HC3: 8508016 | HD3: -170356 | HE3: 4076 | HF3: -24560 | HG3: 80612 | HH3: 72188 | HI3: 84164 | HJ3: -30233125 | HK3: -20955118 | HL3: -19163741 | HM3: 711235 | HN3: 541206 | HO3: 494183 | HP3: -17327305 | HQ3: -15574035 | HR3: 188543 | HS3: 33375269 | HT3: -476011 | HU3: 14421999 | HV3: -9178235 | HW3: -8164592 | HX3: -228074335 | HY3: -381273607 | HZ3: -233934637 | IA3: -167187176 | IB3: 103992518 | IC3: -59384222 | ID3: -53409336 | IE3: -205937632 | IF3: -165515272 | IG3: -11250776 | IH3: -1068744 | II3: -31844267 | IJ3: -21918614 | IK3: -19808735 | IL3: 915997 | IM3: 18706 | IN3: 21073 | IO3: -18228599 | IP3: -16349741 | IQ3: 85473 | IR3: 205402873 | IS3: 142292698 | IT3: 130011949 | IU3: 27191151 | IV3: 66773837 | IW3: 29046599 | IX3: -118360822 | IY3: -107380346 | IZ3: 530090 | JA3: 24262616 | JB3: -1433595 | JC3: 15953 | JD3: -182085 | JE3: 503773 | JF3: 422960 | JG3: 12744396 | JH3: -270554520 | JI3: -61805319 | JJ3: -40221120 | JK3: 1392020 | JL3: 5166217 | JM3: 4207616 | JN3: -102924385 | JO3: -84931520 | JP3: -4100784 | JQ3: 60796 | JR3: -81495 | JS3: 578546 | JT3: 611425 | JU3: -6815 | JV3: 14926 | JW3: 11133 | JX3: 44845 | JY3: 53615 | JZ3: -44167 | KA3: -10749220 | KB3: -7764212 | KC3: -7141156 | KD3: 112699235 | KE3: 117677320 | KF3: 10128069 | KG3: 3509375 | KH3: 2768900 | KI3: -331435 | KJ3: 9388675 | KK3: -2917049 | KL3: 283944795 | KM3: 71105726 | KN3: 46909000 | KO3: -2789226 | KP3: -1816329 | KQ3: -1382632 | KR3: 108811071 | KS3: 89731560 | KT3: 4494568 | KU3: -1973698372 | KV3: -506356667 | KW3: -335171296 | KX3: 1177931657 | KY3: 886487680 | KZ3: 27395304 | LA3: 744774054 | LB3: 615015392 | LC3: 31306840 | LD3: -32534392 | LE3: -11875727 | LF3: -4192670 | LG3: -3233435 | LH3: 118631752 | LI3: 123768425 | LJ3: 11395690 | LK3: 3385587 | LL3: 2537146 | LM3: -26075 | LN3: 9939829 | LO3: -775342619 | LP3: -823236972 | LQ3: -79535425 | LR3: 143074147 | LS3: 69046970
A4: 1-2-3-6 | B4: 1930517 | C4: -59868808 | D4: 1381367 | E4: 137656228 | F4: 8196441 | G4: 78290561 | H4: -91786637 | I4: -51618752 | J4: 2600213 | K4: -85841 | L4: 11507450 | M4: -958090 | N4: 19952049 | O4: 2476755 | P4: 176839 | Q4: 801521 | R4: -542275892 | S4: 18672311 | T4: -724198505 | U4: 46818773 | V4: 64041192 | W4: 14354994 | X4: -321097 | Y4: 17757752 | Z4: -2309096 | AA4: -2168707 | AB4: -117174410 | AC4: 956012866 | AD4: 723728870 | AE4: 320299276 | AF4: 123565447 | AG4: -35036875 | AH4: -24866893 | AI4: 1049065104 | AJ4: 540655531 | AK4: 57816401 | AL4: 22032665 | AM4: 172396 | AN4: -35625523 | AO4: 1464937 | AP4: -12563610 | AQ4: 38174353 | AR4: 20934063 | AS4: -21111619 | AT4: -466235708 | AU4: -138974933 | AV4: -503896805 | AW4: -136310007 | AX4: -60086872 | AY4: -37784337 | AZ4: 316279 | BA4: -15981178 | BB4: 35511959 | BC4: 19588789 | BD4: 255713987 | BE4: 548911519 | BF4: 1028217049 | BG4: 540145004 | BH4: -112750951 | BI4: 231728326 | BJ4: 128050171 | BK4: 950791939 | BL4: 513034419 | BM4: 25405225 | BN4: 1211889 | BO4: -179316597 | BP4: 12907643 | BQ4: -244631295 | BR4: 23150242 | BS4: 26177852 | BT4: 556479 | BU4: 20419 | BV4: -1223082 | BW4: -1918609 | BX4: -946631 | BY4: -8948260 | BZ4: 293303331 | CA4: 273255895 | CB4: 128047391 | CC4: -8905089 | CD4: -20824865 | CE4: -10523489 | CF4: 410653491 | CG4: 217506081 | CH4: 23360494 | CI4: 197465427 | CJ4: -4723852 | CK4: 262121250 | CL4: -14684855 | CM4: -21778492 | CN4: -1404211253 | CO4: 1075620435 | CP4: -1599267091 | CQ4: -1042979720 | CR4: 1838258690 | CS4: -66168229 | CT4: -129920068 | CU4: -2042922475 | CV4: -1265850740 | CW4: -98820436 | CX4: -5496189 | CY4: 319650876 | CZ4: 305875482 | DA4: 144243921 | DB4: -351026 | DC4: -7726017 | DD4: -4056840 | DE4: 429799240 | DF4: 226727846 | DG4: 23008107 | DH4: -2243154919 | DI4: -2219647635 | DJ4: -1054773759 | DK4: 4254988118 | DL4: 2474058865 | DM4: 447356127 | DN4: 3011450117 | DO4: 1588349234 | DP4: 155663373 | DQ4: 308537647 | DR4: -507179 | DS4: -4310 | DT4: 1157242 | DU4: -28584 | DV4: 985942 | DW4: 82053 | DX4: 53498 | DY4: 496569 | DZ4: 276428 | EA4: 3039783 | EB4: -10007601 | EC4: -26658491 | ED4: -15220176 | EE4: 1135382 | EF4: -2154 | EG4: 880272 | EH4: -146207 | EI4: -76962 | EJ4: -6951522 | EK4: 23371942 | EL4: 60872014 | EM4: 34757384 | EN4: 5345238 | EO4: -1010655 | EP4: -537150 | EQ4: 50204311 | ER4: 28531986 | ES4: -349610 | ET4: -28357 | EU4: 4581888 | EV4: -290206 | EW4: 6569701 | EX4: 761202 | EY4: 118515 | EZ4: -25766 | FA4: -868 | FB4: 704 | FC4: 1881 | FD4: -1984 | FE4: 403940 | FF4: -6083174 | FG4: -995580 | FH4: 212886 | FI4: -193892 | FJ4: -4050 | FK4: -23932 | FL4: -416889 | FM4: 462592 | FN4: 61119 | FO4: -4501492 | FP4: 114177 | FQ4: -5872728 | FR4: 745231 | FS4: 734943 | FT4: 27619768 | FU4: -93990004 | FV4: -241249416 | FW4: -137564652 | FX4: -33649263 | FY4: 10691620 | FZ4: 7998609 | GA4: -330298591 | GB4: -194814759 | GC4: -16613853 | GD4: 241534 | GE4: -5447888 | GF4: 378542 | GG4: 982738 | GH4: -176928 | GI4: 30385 | GJ4: 14508 | GK4: -408056 | GL4: 392640 | GM4: -100891 | GN4: 28383394 | GO4: -15267200 | GP4: -13411006 | GQ4: 299873678 | GR4: 187005634 | GS4: 41099922 | GT4: 7612865 | GU4: 8118924 | GV4: -770065 | GW4: 35619523 | GX4: -3898 | GY4: 3847989 | GZ4: 58639 | HA4: 7951720 | HB4: 10965496 | HC4: 6110291 | HD4: 23806 | HE4: 718 | HF4: 59996 | HG4: 92554 | HH4: 51514 | HI4: -350666 | HJ4: -10663238 | HK4: -24397685 | HL4: -13536100 | HM4: 562142 | HN4: 627489 | HO4: 350554 | HP4: -20030168 | HQ4: -11039478 | HR4: 168115 | HS4: -3769615 | HT4: -80775 | HU4: -7708458 | HV4: -10531214 | HW4: -5865489 | HX4: 23031005 | HY4: -80262031 | HZ4: -208235653 | IA4: -118806428 | IB4: -48815781 | IC4: -68804023 | ID4: -38381823 | IE4: -201590656 | IF4: -118059351 | IG4: -7897885 | IH4: -201040 | II4: -10942604 | IJ4: -25189037 | IK4: -13995412 | IL4: 176628 | IM4: 21899 | IN4: 12924 | IO4: -20938406 | IP4: -11592516 | IQ4: 94795 | IR4: 71135924 | IS4: 165001607 | IT4: 91843132 | IU4: 68154711 | IV4: 46888476 | IW4: 20764920 | IX4: -137216963 | IY4: -76117728 | IZ4: 602905 | JA4: 17517345 | JB4: 179931 | JC4: 5509 | JD4: 394098 | JE4: 607244 | JF4: 340723 | JG4: -2731554 | JH4: -21991749 | JI4: -93287730 | JJ4: -54301587 | JK4: 5309521 | JL4: 6362426 | JM4: 3509989 | JN4: -130106264 | JO4: -77291029 | JP4: -6608298 | JQ4: -502 | JR4: 362556 | JS4: 563695 | JT4: 297002 | JU4: 12200 | JV4: 18953 | JW4: 10044 | JX4: 11066 | JY4: -36032 | JZ4: -65087 | KA4: -5565362 | KB4: -8817790 | KC4: -4660322 | KD4: 119075575 | KE4: 73115654 | KF4: 16133355 | KG4: 4176757 | KH4: 1907236 | KI4: -475697 | KJ4: 14065769 | KK4: 1598995 | KL4: 25296864 | KM4: 101124737 | KN4: 58750957 | KO4: -2727714 | KP4: -2300237 | KQ4: -1229112 | KR4: 136117110 | KS4: 80777694 | KT4: 6783947 | KU4: -188600371 | KV4: -706165508 | KW4: -409342723 | KX4: 755718497 | KY4: 453638125 | KZ4: 58301739 | LA4: 933331243 | LB4: 553321866 | LC4: 46046909 | LD4: 27778663 | LE4: -3292508 | LF4: -5291529 | LG4: -2803284 | LH4: 124512532 | LI4: 76625444 | LJ4: 17136411 | LK4: 4290338 | LL4: 2251224 | LM4: -34812 | LN4: 14713238 | LO4: -829940839 | LP4: -512236616 | LQ4: -116614761 | LR4: 56277087 | LS4: 100010534
A5: 1-2-3-7 | B5: 2794940 | C5: 48126896 | D5: 1758084 | E5: 141120704 | F5: 1938444 | G5: 267268572 | H5: -128613500 | I5: -11150992 | J5: -1261498 | K5: -115262 | L5: 18829058 | M5: -1016932 | N5: 23147094 | O5: 3426480 | P5: -2114534 | Q5: -1191218 | R5: 387918024 | S5: -16635934 | T5: 519208482 | U5: 951782 | V5: -41443792 | W5: 17663678 | X5: -559734 | Y5: 25582104 | Z5: -3148622 | AA5: -1789954 | AB5: -64405402 | AC5: -631813650 | AD5: 1039456418 | AE5: -31643560 | AF5: 113298786 | AG5: -44419252 | AH5: -5523806 | AI5: 1392809574 | AJ5: -109854030 | AK5: 110974214 | AL5: -22633390 | AM5: 347410 | AN5: -28044670 | AO5: 6137080 | AP5: -80454930 | AQ5: 53539360 | AR5: 4587390 | AS5: 20219098 | AT5: 659884296 | AU5: 121373686 | AV5: 778960470 | AW5: -119600526 | AX5: -11308976 | AY5: -35182018 | AZ5: 3619422 | BA5: -83829456 | BB5: 49664146 | BC5: 4271642 | BD5: 329320870 | BE5: -1380493842 | BF5: 1412763426 | BG5: 119734168 | BH5: -642663522 | BI5: 319539736 | BJ5: 27666758 | BK5: 1417489518 | BL5: 117681558 | BM5: 2510498 | BN5: -1090194 | BO5: 165135462 | BP5: -11005078 | BQ5: 223758270 | BR5: 3582568 | BS5: -19193992 | BT5: -1183896 | BU5: -126686 | BV5: 440748 | BW5: -2633848 | BX5: 73654 | BY5: 31140530 | BZ5: -309751884 | CA5: 395067592 | CB5: 9687086 | CC5: -21552654 | CD5: -27003968 | CE5: 2973946 | CF5: 542035896 | CG5: -22877034 | CH5: 46129576 | CI5: -179305530 | CJ5: 3984904 | CK5: -237410676 | CL5: 2560442 | CM5: 17691304 | CN5: 1206411318 | CO5: -840376602 | CP5: -977068326 | CQ5: 477096048 | CR5: -1578680292 | CS5: 38941742 | CT5: 108428376 | CU5: -1305694182 | CV5: 548785848 | CW5: -103215944 | CX5: 25163606 | CY5: -330306444 | CZ5: 435972688 | DA5: 7097906 | DB5: -25977276 | DC5: -9329770 | DD5: 2325040 | DE5: 572535828 | DF5: -23191884 | DG5: 42914190 | DH5: 2104444446 | DI5: -3070451578 | DJ5: 19198866 | DK5: 3843234564 | DL5: -845612430 | DM5: 1198713646 | DN5: 3949988358 | DO5: -214263876 | DP5: 276582050 | DQ5: 1195894206 | DR5: -861869 | DS5: -6011 | DT5: 1730479 | DU5: -31986 | DV5: 1281727 | DW5: 114750 | DX5: 17273 | DY5: 438631 | DZ5: 73314684 | EA5: 46977 | EB5: 104487409 | EC5: -37684325 | ED5: -3141176 | EE5: 1392017 | EF5: -15951 | EG5: 1381044 | EH5: -204425 | EI5: -13117 | EJ5: -2815203 | EK5: -100762247 | EL5: 85424575 | EM5: 7776244 | EN5: 3947637 | EO5: -1392300 | EP5: -115635 | EQ5: 69953725 | ER5: 6765461 | ES5: -337025 | ET5: -32830 | EU5: 5025219 | EV5: -299152 | EW5: 6559306 | EX5: 1004823 | EY5: -659850 | EZ5: -30869 | FA5: -868 | FB5: -3076 | FC5: 2637 | FD5: -5260 | FE5: 414146 | FF5: -5696669 | FG5: -1348443 | FH5: 1425573 | FI5: -201452 | FJ5: -2538 | FK5: -30484 | FL5: -621009 | FM5: 1112752 | FN5: 107991 | FO5: -5350161 | FP5: 150458 | FQ5: -7318324 | FR5: 924073 | FS5: 455470 | FT5: 25721199 | FU5: 51259143 | FV5: -305197503 | FW5: 37815024 | FX5: -36624770 | FY5: 13025341 | FZ5: 1126258 | GA5: -408617053 | GB5: 56089826 | GC5: -32513442 | GD5: 282925 | GE5: -6379904 | GF5: 439136 | GG5: 1285463 | GH5: -207588 | GI5: 36517 | GJ5: -12064 | GK5: -501248 | GL5: 1215212 | GM5: -184639 | GN5: 33382411 | GO5: -18250499 | GP5: -4180217 | GQ5: 359731424 | GR5: -57409105 | GS5: 76432473 | GT5: 9082121 | GU5: 4490548 | GV5: -1317745 | GW5: 64009387 | GX5: 155807 | GY5: -22661466 | GZ5: 2151499 | HA5: -35189105 | HB5: 15580561 | HC5: 1274726 | HD5: 154783 | HE5: 9223 | HF5: -13714 | HG5: 129409 | HH5: 12013 | HI5: -3478805 | HJ5: 36952477 | HK5: -34300151 | HL5: -3013588 | HM5: 1893647 | HN5: 864684 | HO5: 90427 | HP5: -27855713 | HQ5: -2600943 | HR5: 142537 | HS5: 24786786 | HT5: -1086470 | HU5: 36797822 | HV5: -14741914 | HW5: -1216602 | HX5: -184251942 | HY5: 246023754 | HZ5: -334507746 | IA5: -25842072 | IB5: 262751804 | IC5: -94921288 | ID5: -7910854 | IE5: -350279196 | IF5: -26288966 | IG5: -1048994 | IH5: -2546584 | II5: 38737690 | IJ5: -35232248 | IK5: -3119712 | IL5: 2082618 | IM5: 29744 | IN5: 11752 | IO5: -29265686 | IP5: -2730094 | IQ5: 126152 | IR5: -262679254 | IS5: 227530832 | IT5: 20535296 | IU5: 173079618 | IV5: 9421912 | IW5: 5369536 | IX5: -189144728 | IY5: -18006154 | IZ5: 810160 | JA5: 5079934 | JB5: 45237 | JC5: 27874 | JD5: -154632 | JE5: 775139 | JF5: -70730 | JG5: -4678821 | JH5: 32707371 | JI5: -117264333 | JJ5: 9917274 | JK5: 4160086 | JL5: 7916321 | JM5: -1204742 | JN5: -159602549 | JO5: 17239526 | JP5: -13414692 | JQ5: 25013 | JR5: -149634 | JS5: 732472 | JT5: -73753 | JU5: -6700 | JV5: 22733 | JW5: -6336 | JX5: 60206 | JY5: 18148 | JZ5: -118511 | KA5: -2608457 | KB5: -10919659 | KC5: 2144623 | KD5: 141709270 | KE5: -20520931 | KF5: 30604833 | KG5: 5295637 | KH5: -1235204 | KI5: -816905 | KJ5: 25443569 | KK5: 4749822 | KL5: -35283738 | KM5: 127594296 | KN5: -10898958 | KO5: -5504884 | KP5: -2767842 | KQ5: 710864 | KR5: 168438230 | KS5: -17912132 | KT5: 12744814 | KU5: 215135928 | KV5: -884368170 | KW5: 85969170 | KX5: 790281726 | KY5: -144964638 | KZ5: 280112430 | LA5: 1150318148 | LB5: -131832876 | LC5: 82259170 | LD5: 290840966 | LE5: -3798158 | LF5: -6357528 | LG5: 1717576 | LH5: 149256256 | LI5: -21474166 | LJ5: 31551176 | LK5: 5154878 | LL5: -1422176 | LM5: -49400 | LN5: 26742426 | LO5: -995132602 | LP5: 146539554 | LQ5: -204727280 | LR5: -132248974 | LS5: 173731630
A6: 1-2-3-8 | B6: 4880807 | C6: -342526376 | D6: 1991421 | E6: 429237644 | F6: -735517 | G6: 330641595 | H6: -205339615 | I6: -48718640 | J6: 13701317 | K6: -161063 | L6: 26065742 | M6: -1622236 | N6: 45495777 | O6: 5265639 | P6: -2602217 | Q6: 5712833 | R6: -3034196020 | S6: 115910375 | T6: -4120984281 | U6: 206892613 | V6: 319381096 | W6: 24799622 | X6: -686161 | Y6: 29473686 | Z6: -4627618 | AA6: -2669411 | AB6: -138737910 | AC6: 2235302814 | AD6: 1559688778 | AE6: 31330476 | AF6: 103039473 | AG6: -69042329 | AH6: -15800493 | AI6: 2270756580 | AJ6: 277841595 | AK6: 162037345 | AL6: 133034885 | AM6: 1043056 | AN6: -122921473 | AO6: 12384097 | AP6: -85446420 | AQ6: 85705333 | AR6: 19841643 | AS6: -127479463 | AT6: -3073207756 | AU6: -849046161 | AV6: -3015733665 | AW6: -417759819 | AX6: -64540024 | AY6: -141883771 | AZ6: 5210027 | BA6: -105523020 | BB6: 78850919 | BC6: 18507049 | BD6: 1070583161 | BE6: 812597565 | BF6: 2365860251 | BG6: 517990796 | BH6: -826062225 | BI6: 508093842 | BJ6: 120624007 | BK6: 2211153405 | BL6: 491238255 | BM6: 20728525 | BN6: 7318101 | BO6: -1055530173 | BP6: 78981287 | BQ6: -1479930255 | BR6: 97066378 | BS6: 126627068 | BT6: -1514079 | BU6: -61985 | BV6: -6903036 | BW6: -3953509 | BX6: -98651 | BY6: 25281278 | BZ6: 689472783 | CA6: 590319019 | CB6: 40427495 | CC6: -87036807 | CD6: -41846453 | CE6: 7843 | CF6: 891074103 | CG6: 139395153 | CH6: 67100134 | CI6: 1180505883 | CJ6: -28978012 | CK6: 1584021798 | CL6: -70032467 | CM6: -117788956 | CN6: -8561060845 | CO6: 10259980011 | CP6: -5556912683 | CQ6: -3437258056 | CR6: 11235516366 | CS6: -371471193 | CT6: -769833956 | CU6: -6847690659 | CV6: -3588444084 | CW6: -350547412 | CX6: 15994403 | CY6: 785824146 | CZ6: 652242340 | DA6: 40283657 | DB6: -40751262 | DC6: -15061813 | DD6: 607048 | DE6: 921807594 | DF6: 132461514 | DG6: 62689887 | DH6: -5837828241 | DI6: -4654789897 | DJ6: -245567559 | DK6: 9367805526 | DL6: 2638182441 | DM6: 1709498023 | DN6: 6362243427 | DO6: 847235742 | DP6: 407916041 | DQ6: 1515635415 | DR6: -1101332 | DS6: -9476 | DT6: 2848918 | DU6: -51957 | DV6: 2367091 | DW6: 182160 | DX6: 57845 | DY6: 1114364 | DZ6: -103076480 | EA6: 3480284 | EB6: -91510468 | EC6: -59117620 | ED6: -15052600 | EE6: 1995746 | EF6: -22627 | EG6: 1607733 | EH6: -324340 | EI6: -70985 | EJ6: -4139986 | EK6: 15176542 | EL6: 135876230 | EM6: 33524100 | EN6: 3163024 | EO6: -2213325 | EP6: -527335 | EQ6: 111925595 | ER6: 27546145 | ES6: -615325 | ET6: -62944 | EU6: 13879050 | EV6: -511903 | EW6: 16910773 | EX6: 1699524 | EY6: -424797 | EZ6: -43406 | FA6: -1435 | FB6: 10217 | FC6: 4212 | FD6: -6961 | FE6: 669422 | FF6: -13914452 | FG6: -2100726 | FH6: 1827828 | FI6: -302441 | FJ6: -4491 | FK6: -46927 | FL6: -855747 | FM6: 1801216 | FN6: 159525 | FO6: -8152190 | FP6: 319053 | FQ6: -11880815 | FR6: 1659092 | FS6: 1290119 | FT6: -4051570 | FU6: 429502270 | FV6: -585940890 | FW6: -229451580 | FX6: -10904804 | FY6: 22107467 | FZ6: 8338889 | GA6: -766526729 | GB6: -266426903 | GC6: -46030845 | GD6: 405872 | GE6: -9516230 | GF6: 598588 | GG6: 1791216 | GH6: -219071 | GI6: 59174 | GJ6: -5872 | GK6: -1064326 | GL6: 1104493 | GM6: -269810 | GN6: 16654086 | GO6: -28874668 | GP6: -10533456 | GQ6: 652444726 | GR6: 173472732 | GS6: 111896280 | GT6: 13157137 | GU6: 5926419 | GV6: -1953470 | GW6: 95127185 | GX6: -22924 | GY6: 49915542 | GZ6: 1378237 | HA6: 45238585 | HB6: 24304108 | HC6: 6053843 | HD6: 370180 | HE6: 12940 | HF6: 339968 | HG6: 205324 | HH6: 50884 | HI6: -5920055 | HJ6: -9739469 | HK6: -54613682 | HL6: -13038337 | HM6: 5096441 | HN6: 1374543 | HO6: 357988 | HP6: -44754329 | HQ6: -10635459 | HR6: 275215 | HS6: -48360674 | HT6: -1466987 | HU6: -43869119 | HV6: -23361176 | HW6: -5812161 | HX6: 286729234 | HY6: 86476642 | HZ6: -404697350 | IA6: -115632580 | IB6: -257475708 | IC6: -150784041 | ID6: -37967791 | IE6: -408884133 | IF6: -115286143 | IG6: -7219645 | IH6: -3609225 | II6: -8794763 | IJ6: -55913754 | IK6: -13489739 | IL6: 3007231 | IM6: 47373 | IN6: 24568 | IO6: -46472287 | IP6: -11179877 | IQ6: 203545 | IR6: 45690058 | IS6: 361714389 | IT6: 88610149 | IU6: 173580107 | IV6: 45150497 | IW6: 20805955 | IX6: -300783201 | IY6: -73519571 | IZ6: 1299135 | JA6: 17924600 | JB6: 2563914 | JC6: 89425 | JD6: 2233509 | JE6: 1353668 | JF6: 354835 | JG6: -40569543 | JH6: 196345713 | JI6: -229254456 | JJ6: -95543907 | JK6: 42189658 | JL6: 13423466 | JM6: 2282245 | JN6: -303375542 | JO6: -110404837 | JP6: -18716394 | JQ6: 3215 | JR6: 1956393 | JS6: 1105054 | JT6: -38851 | JU6: 65435 | JV6: 36845 | JW6: -1800 | JX6: -70267 | JY6: -304601 | JZ6: -173447 | KA6: -31202771 | KB6: -17198113 | KC6: 734557 | KD6: 259558015 | KE6: 69929492 | KF6: 44653581 | KG6: 7560676 | KH6: -2519207 | KI6: -1210529 | KJ6: 37900307 | KK6: 24577943 | KL6: -194671425 | KM6: 242900482 | KN6: 98507189 | KO6: -28200458 | KP6: -4504441 | KQ6: 34280 | KR6: 314379067 | KS6: 112754534 | KT6: 18392363 | KU6: 1198151344 | KV6: -1645826887 | KW6: -642813659 | KX6: 1194726769 | KY6: 289321613 | KZ6: 243553035 | LA6: 2107990650 | LB6: 735886114 | LC6: 120105053 | LD6: 224759239 | LE6: -18998291 | LF6: -10288578 | LG6: 495952 | LH6: 269248984 | LI6: 72215993 | LJ6: 46137542 | LK6: 8323151 | LL6: -542552 | LM6: -76544 | LN6: 39327021 | LO6: -1773751843 | LP6: -472705767 | LQ6: -302299082 | LR6: -43040881 | LS6: 257747083
